<?xml version="1.0" encoding="UTF-8"?>
<!-- Generated by org.testng.reporters.JUnitXMLReporter -->
<testsuite ignored="3" hostname="DESKTOP-JAS0CHU" failures="1" tests="2" name="Test" time="0.072" errors="0" timestamp="2025-01-26T14:50:10 IST">
  <testcase classname="Testng.Firstclass" name="thirdTestcase" time="0.012">
    <failure type="java.io.IOException" message="Error">
      <![CDATA[java.io.IOException: Error
at Testng.Firstclass.thirdTestcase(Firstclass.java:28)
at java.base/java.util.concurrent.FutureTask.run(FutureTask.java:317)
at java.base/java.util.concurrent.ThreadPoolExecutor.runWorker(ThreadPoolExecutor.java:1144)
at java.base/java.util.concurrent.ThreadPoolExecutor$Worker.run(ThreadPoolExecutor.java:642)
at java.base/java.lang.Thread.run(Thread.java:1583)
... Removed 6 stack frames]]>
    </failure>
  </testcase> <!-- thirdTestcase -->
  <testcase classname="Testng.Firstclass" name="fifthTestcase" time="0.004"/>
  <testcase classname="Testng.Firstclass" name="firstTestcase" time="0.0">
    <ignored/>
  </testcase> <!-- firstTestcase -->
  <testcase classname="Testng.SecondClass" name="fourthTEstcase" time="0.0">
    <ignored/>
  </testcase> <!-- fourthTEstcase -->
  <testcase classname="Testng.Firstclass" name="secondTestcase" time="0.0">
    <ignored/>
  </testcase> <!-- secondTestcase -->
</testsuite> <!-- Test -->
