<?xml version="1.0" encoding="UTF-8"?>
<!-- Generated by org.testng.reporters.JUnitReportReporter -->
<testsuite hostname="DESKTOP-JAS0CHU" failures="0" tests="3" name="Testng.Firstclass" time="0.016" errors="1" timestamp="2025-01-26T14:50:10 IST" skipped="1">
  <testcase classname="Testng.Firstclass" name="thirdTestcase" time="0.012">
    <error message="Error" type="java.io.IOException">
      <![CDATA[java.io.IOException: Error
at Testng.Firstclass.thirdTestcase(Firstclass.java:28)
at java.base/jdk.internal.reflect.DirectMethodHandleAccessor.invoke(DirectMethodHandleAccessor.java:103)
at java.base/java.lang.reflect.Method.invoke(Method.java:580)
at org.testng.internal.invokers.MethodInvocationHelper.invokeMethod(MethodInvocationHelper.java:139)
at org.testng.internal.invokers.InvokeMethodRunnable.runOne(InvokeMethodRunnable.java:47)
at org.testng.internal.invokers.InvokeMethodRunnable.call(InvokeMethodRunnable.java:76)
at org.testng.internal.invokers.InvokeMethodRunnable.call(InvokeMethodRunnable.java:11)
at java.base/java.util.concurrent.FutureTask.run(FutureTask.java:317)
at java.base/java.util.concurrent.ThreadPoolExecutor.runWorker(ThreadPoolExecutor.java:1144)
at java.base/java.util.concurrent.ThreadPoolExecutor$Worker.run(ThreadPoolExecutor.java:642)
at java.base/java.lang.Thread.run(Thread.java:1583)
]]>
    </error>
  </testcase> <!-- thirdTestcase -->
  <testcase classname="Testng.Firstclass" name="fifthTestcase" time="0.004"/>
  <testcase classname="Testng.Firstclass" name="secondTestcase">
    <skipped/>
  </testcase> <!-- secondTestcase -->
</testsuite> <!-- Testng.Firstclass -->
